Workbook

Sheet Project Overview  
A1: 2025 Tennis Tournament Performance Analysis
A2: Analysing the relationship between pre-tournament ATP rankings and actual tournament performance
A4: Research Question:
A6: How closely did pre-tournament ATP rankings predict men's singles performance across the 2025 Grand Slam tournaments?
A9: Project Objectives:
A11: • Compare players' pre-tournament rankings with their actual tournament results
A12: • Measure the difference between expected and actual performance
A13: • Analyse variation in player performance using statistical measures
A14: • Identify major deviations and unexpected tournament results
A15: • Compare performance patterns across the four Grand Slam tournaments
A16: • Use Excel, Python and SQL to clean, analyse and interpret the dataset
A19: Tournaments Analysed:
... A58: • Python — Data analysis and validation using pandas

Sheet Tournament List
A1: 2025 Grand Slam Tournament List
A2: Key tournament details and classifications for the 2025 Grand Slam's
A4: Tournament | B4: Start Date | C4: End Date | D4: Surface | E4: Location | F4: Tournament Level | G4: Draw Size
A5: Australian Open | B5: 45669 | C5: 45683 | D5: Hard | E5: Melbourne, Australia | F5: Grand Slam | G5: 128
A6: Roland Garros | B6: 45802 | C6: 45816 | D6: Clay | E6: Paris, France | F6: Grand Slam | G6: 128
A7: Wimbledon | B7: 45838 | C7: 45851 | D7: Grass | E7: London, United Kingdom | F7: Grand Slam | G7: 128
A8: US Open | B8: 45893 | C8: 45907 | D8: Hard | E8: New York, United States | F8: Grand Slam | G8: 128

Sheet Raw Data
A1: 2025 GRAND SLAM MEN'S SINGLES - RAW DATA
A2: Player rankings, tournament results and match-level information used for the analysis
A4: Tournament | B4: Player | C4: Ranking Before Tournament | D4: Seed | E4: ActualRound | F4: ActualScore | G4: Matches Played | H4: Matches Won | I4: Matches Lost | J4: Expected Round | K4: ExpectedScore | L4: PerformanceDeviation
A5: Australian Open | B5: Jannik Sinner | C5: 1 | D5: 1 | E5: Final | F5: 8 | G5: 7 | H5: 7 | I5: 0 | J5: Final | K5: 7 | L5: 1
A6: Australian Open | B6: Alexander Zverev | C6: 2 | D6: 2 | E6: Final | F6: 7 | G6: 7 | H6: 6 | I6: 1 | J6: Final | K6: 7 | L6: 0
A7: Australian Open | B7: Nicolas Jarry | C7: 34 | E7: R128 | F7: 1 | G7: 1 | H7: 0 | I7: 1 | J7: R64 | K7: 2 | L7: -1
A8: Australian Open | B8: Tristan Schoolkate | C8: 173 | E8: R64 | F8: 2 | G8: 2 | H8: 1 | I8: 1 | J8: R128 | K8: 1 | L8: 1
A9: Australian Open | B9: Taro Daniel | C9: 84 | E9: R128 | F9: 1 | G9: 1 | H9: 0 | I9: 1 | J9: R128 | K9: 1 | L9: 0
A10: Australian Open | B10: Marcos Giron | C10: 45 | E10: R32 | F10: 3 | G10: 3 | H10: 2 | I10: 1 | J10: R64 | K10: 2 | L10: 1
A11: Australian Open | B11: Yannick Hanfmann | C11: 98 | E11: R128 | F11: 1 | G11: 1 | H11: 0 | I11: 1 | J11: R128 | K11: 1 | L11: 0
A12: Australian Open | B12: Tomas Martin Etcheverry | C12: 39 | E12: R64 | F12: 2 | G12: 2 | H12: 1 | I12: 1 | J12: R64 | K12: 2 | L12: 0
A13: Australian Open | B13: Flavio Cobolli | C13: 32 | D13: 32 | E13: R128 | F13: 1 | G13: 1 | H13: 0 | I13: 1 | J13: R32 | K13: 3 | L13: -2
A14: Australian Open | B14: Stan Wawrinka | C14: 158 | E14: R128 | F14: 1 | G14: 1 | H14: 0 | I14: 1 | J14: R128 | K14: 1 | L14: 0
A15: Australian Open | B15: Hubert Hurkacz | C15: 18 | D15: 18 | E15: R64 | F15: 2 | G15: 2 | H15: 1 | I15: 1 | J15: R32 | K15: 3 | L15: -1
A16: Australian Open | B16: Tallon Griekspoor | C16: 40 | E16: R128 | F16: 1 | G16: 1 | H16: 0 | I16: 1 | J16: R64 | K16: 2 | L16: -1
A17: Australian Open | B17: Dusan Lajovic | C17: 75 | E17: R128 | F17: 1 | G17: 1 | H17: 0 | I17: 1 | J17: R128 | K17: 1 | L17: 0
A18: Australian Open | B18: Miomir Kecmanovic | C18: 55 | E18: R32 | F18: 3 | G18: 3 | H18: 2 | I18: 1 | J18: R64 | K18: 2 | L18: 1
A19: Australian Open | B19: Matteo Berrettini | C19: 35 | E19: R64 | F19: 2 | G19: 2 | H19: 1 | I19: 1 | J19: R64 | K19: 2 | L19: 0
A20: Australian Open | B20: Gael Monfils | C20: 52 | E20: R16 | F20: 4 | G20: 4 | H20: 3 | I20: 1 | J20: R64 | K20: 2 | L20: 2
A21: Australian Open | B21: Cameron Norrie | C21: 48 | E21: R128 | F21: 1 | G21: 1 | H21: 0 | I21: 1 | J21: R64 | K21: 2 | L21: -1
A22: Australian Open | B22: Holger Rune | C22: 13 | D22: 13 | E22: R16 | F22: 4 | G22: 4 | H22: 3 | I22: 1 | J22: R16 | K22: 4 | L22: 0
A23: Australian Open | B23: Novak Djokovic | C23: 7 | D23: 7 | E23: Semi-final | F23: 6 | G23: 6 | H23: 5 | I23: 1 | J23: Quarter-final | K23: 5 | L23: 1
A24: Australian Open | B24: Zhizhen Zhang | C24: 47 | E24: R128 | F24: 1 | G24: 1 | H24: 0 | I24: 1 | J24: R64 | K24: 2 | L24: -1
A25: Australian Open | B25: Alex Michelsen | C25: 41 | E25: R16 | F25: 4 | G25: 4 | H25: 3 | I25: 1 | J25: R64 | K25: 2 | L25: 2
A26: Australian Open | B26: Adrian Mannarino | C26: 73 | E26: R128 | F26: 1 | G26: 1 | H26: 0 | I26: 1 | J26: R128 | K26: 1 | L26: 0
A27: Australian Open | B27: Stefanos Tsitsipas | C27: 11 | D27: 11 | E27: R128 | F27: 1 | G27: 1 | H27: 0 | I27: 1 | J27: R16 | K27: 4 | L27: -3
A28: Australian Open | B28: James Mccabe | C28: 258 | E28: R64 | F28: 2 | G28: 2 | H28: 1 | I28: 1 | J28: R128 | K28: 1 | L28: 1
A29: Australian Open | B29: Martin Landaluce | C29: 143 | E29: R128 | F29: 1 | G29: 1 | H29: 0 | I29: 1 | J29: R128 | K29: 1 | L29: 0
A30: Australian Open | B30: Roberto Bautista Agut | C30: 51 | E30: R128 | F30: 1 | G30: 1 | H30: 0 | I30: 1 | J30: R64 | K30: 2 | L30: -1
A31: Australian Open | B31: Gabriel Diallo | C31: 87 | E31: R64 | F31: 2 | G31: 2 | H31: 1 | I31: 1 | J31: R128 | K31: 1 | L31: 1
A32: Australian Open | B32: Luca Nardi | C32: 90 | E32: R128 | F32: 1 | G32: 1 | H32: 0 | I32: 1 | J32: R128 | K32: 1 | L32: 0
A33: Australian Open | B33: Karen Khachanov | C33: 19 | D33: 19 | E33: R32 | F33: 3 | G33: 3 | H33: 2 | I33: 1 | J33: R32 | K33: 3 | L33: 0
A34: Australian Open | B34: Federico Coria | C34: 97 | E34: R128 | F34: 1 | G34: 1 | H34: 0 | I34: 1 | J34: R128 | K34: 1 | L34: 0
A35: Australian Open | B35: Francisco Cerundolo | C35: 31 | D35: 31 | E35: R32 | F35: 3 | G35: 3 | H35: 2 | I35: 1 | J35: R32 | K35: 3 | L35: 0
A36: Australian Open | B36: Alexander Bublik | C36: 33 | E36: R128 | F36: 1 | G36: 1 | H36: 0 | I36: 1 | J36: R64 | K36: 2 | L36: -1
A37: Australian Open | B37: Pablo Carreno Busta | C37: 184 | E37: R64 | F37: 2 | G37: 2 | H37: 1 | I37: 1 | J37: R128 | K37: 1 | L37: 1
A38: Australian Open | B38: Facundo Diaz Acosta | C38: 78 | E38: R64 | F38: 2 | G38: 2 | H38: 1 | I38: 1 | J38: R128 | K38: 1 | L38: 1
A39: Australian Open | B39: Zizou Bergs | C39: 66 | E39: R128 | F39: 1 | G39: 1 | H39: 0 | I39: 1 | J39: R128 | K39: 1 | L39: 0
A40: Australian Open | B40: Tristan Boyer | C40: 134 | E40: R64 | F40: 2 | G40: 2 | H40: 1 | I40: 1 | J40: R128 | K40: 1 | L40: 1
A41: Australian Open | B41: Kei Nishikori | C41: 74 | E41: R64 | F41: 2 | G41: 2 | H41: 1 | I41: 1 | J41: R128 | K41: 1 | L41: 1
...

Sheet Tournament Results
A1: 2025 GRAND SLAM TOURNAMENT MATCH RESULTS
A2: Match-level results used to calculate player performance and opponent difficulty
A4: Tournament | B4: Round | C4: Winner | D4: Loser | E4: Winner Ranking | F4: Loser Ranking | G4: Score
A5: Australian Open | B5: R128 | C5: Jannik Sinner | D5: Nicolas Jarry | E5: 1 | F5: 36 | G5: 7-6(2) 7-6(5) 6-1
A6: Australian Open | B6: R128 | C6: Tristan Schoolkate | D6: Taro Daniel | E6: 173 | F6: 113 | G6: 6-7(6) 7-6(4) 6-1 6-4
A7: Australian Open | B7: R128 | C7: Marcos Giron | D7: Yannick Hanfmann | E7: 46 | F7: 95 | G7: 2-6 7-5 6-1 7-5
A8: Australian Open | B8: R128 | C8: Tomas Martin Etcheverry | D8: Flavio Cobolli | E8: 38 | F8: 32 | G8: 6-7(8) 6-3 7-5 6-1
A9: Australian Open | B9: R128 | C9: Hubert Hurkacz | D9: Tallon Griekspoor | E9: 17 | F9: 40 | G9: 7-5 6-4 6-4
A10: Australian Open | B10: R128 | C10: Miomir Kecmanovic | D10: Dusan Lajovic | E10: 51 | F10: 80 | G10: 7-5 3-6 6-3 3-6 6-3
A11: Australian Open | B11: R128 | C11: Matteo Berrettini | D11: Cameron Norrie | E11: 34 | F11: 52 | G11: 6-7(4) 6-4 6-1 6-3
A12: Australian Open | B12: R128 | C12: Holger Rune | D12: Zhizhen Zhang | E12: 13 | F12: 49 | G12: 4-6 6-3 6-4 3-6 6-4
A13: Australian Open | B13: R128 | C13: Alex Michelsen | D13: Stefanos Tsitsipas | E13: 42 | F13: 12 | G13: 7-5 6-3 2-6 6-4
A14: Australian Open | B14: R128 | C14: James Mccabe | D14: Martin Landaluce | E14: 258 | F14: 142 | G14: 6-4 6-3 6-4
A15: Australian Open | B15: R128 | C15: Gabriel Diallo | D15: Luca Nardi | E15: 86 | F15: 83 | G15: 6-7(1) 7-6(3) 5-7 6-1 6-2
A16: Australian Open | B16: R128 | C16: Karen Khachanov | D16: Adrian Mannarino | E16: 19 | F16: 75 | G16: 7-6(5) 6-3 6-3
... A20: Australian Open | B20: R128 | C20: Alex De Minaur | D20: Botic Van De Zandschulp | E20: 8 | F20: 84 | G20: 6-1 7-5 6-4
A21: Australian Open | B21: R128 | C21: Taylor Fritz | D21: Jenson Brooksby | E21: 4 | G21: 6-2 6-0 6-3
A22: Australian Open | B22: R128 | C22: Cristian Garin | D22: Borna Coric | E22: 150 | F22: 87 | G22: 7-5 6-1 6-2
A23: Australian Open | B23: R128 | C23: Daniel Altmaier | D23: Francisco Comesana | E23: 101 | F23: 85 | G23: 6-2 3-6 7-6(4) 4-6 6-4
A24: Australian Open | B24: R128 | C24: Gael Monfils | D24: Giovanni Mpetshi Perricard | E24: 41 | F24: 30 | G24: 7-6(7) 6-3 6-7(6) 6-7(5) 6-4
A25: Australian Open | B25: R128 | C25: Ben Shelton | D25: Brandon Nakashima | E25: 20 | F25: 35 | G25: 7-6(3) 7-5 7-5
A26: Australian Open | B26: R128 | C26: Pablo Carreno Busta | D26: Kamil Majchrzak | E26: 182 | F26: 122 | G26: 6-4 6-4 6-3
A27: Australian Open | B27: R128 | C27: Denis Shapovalov | D27: Roberto Bautista Agut | E27: 56 | F27: 53 | G27: 3-6 6-4 6-4 7-6(8)
A28: Australian Open | B28: R128 | C28: Lorenzo Musetti | D28: Matteo Arnaldi | E28: 15 | F28: 39 | G28: 7-6(4) 4-6 7-6(5) 6-3
A29: Australian Open | B29: R128 | C29: Joao Fonseca | D29: Andrey Rublev | E29: 112 | F29: 9 | G29: 7-6(1) 6-3 7-6(5)
A30: Australian Open | B30: R128 | C30: Lorenzo Sonego | D30: Stan Wawrinka | E30: 55 | F30: 156 | G30: 6-4 5-7 7-5 7-5
A31: Australian Open | B31: R128 | C31: Fabian Marozsan | D31: Thiago Seyboth Wild | E31: 59 | F31: 79 | G31: 6-3 6-7(5) 7-5 5-7 7-5
A32: Australian Open | B32: R128 | C32: Frances Tiafoe | D32: Arthur Rinderknech | E32: 16 | F32: 61 | G32: 7-6(2) 6-3 4-6 6-7(4) 6-3
A33: Australian Open | B33: R128 | C33: Corentin Moutet | D33: Alexei Popyrin | E33: 69 | F33: 24 | G33: 4-6 6-3 6-4 6-4
... A65: Australian Open | B65: R128 | C65: Arthur Cazaux | D65: Sebastian Baez | E65: 78 | F65: 28 | G65: 6-3 5-7 3-6 6-0 6-3
A66: Australian Open | B66: R128 | C66: Jacob Fearnley | D66: Nick Kyrgios | E66: 92 | G66: 7-6(3) 6-3 7-6(2)
A67: Australian Open | B67: R128 | C67: Pedro Martinez | D67: Luciano Darderi | E67: 44 | F67: 45 | G67: 6-3 4-1 RET
A68: Australian Open | B68: R128 | C68: Alexander Zverev | D68: Lucas Pouille | E68: 2 | F68: 103 | G68: 6-4 6-4 6-4
A69: Australian Open | B69: R64 | C69: Jannik Sinner | D69: Tristan Schoolkate | E69: 1 | F69: 173 | G69: 4-6 6-4 6-1 6-3
A70: Australian Open | B70: R64 | C70: Marcos Giron | D70: Tomas Martin Etcheverry | E70: 46 | F70: 38 | G70: 7-5 3-6 7-5 3-6 6-4
A71: Australian Open | B71: R64 | C71: Miomir Kecmanovic | D71: Hubert Hurkacz | E71: 51 | F71: 17 | G71: 6-4 6-4 6-2
A72: Australian Open | B72: R64 | C72: Holger Rune | D72: Matteo Berrettini | E72: 13 | F72: 34 | G72: 7-6(3) 2-6 6-3 7-6(6)
A73: Australian Open | B73: R64 | C73: Alex Michelsen | D73: James Mccabe | E73: 42 | F73: 258 | G73: 7-5 6-3 7-6(4)
A74: Australian Open | B74: R64 | C74: Karen Khachanov | D74: Gabriel Diallo | E74: 19 | F74: 86 | G74: 7-6(4) 4-6 6-3 6-3
A75: Australian Open | B75: R64 | C75: Francisco Cerundolo | D75: Facundo Diaz Acosta | E75: 31 | F75: 73 | G75: 6-2 1-0 RET
...

Sheet Exp. vs Act.
A1: Expected vs Actual Performance
A2: Comparing pre-tournament ATP ranking expectations with actual Grand Slam performance
A4: Tournament | B4: Player | C4: Ranking Before Tournament | D4: Seed | E4: Expected Round | F4: Expected Score | G4: Actual Round | H4: Actual Score | I4: Performance Deviation | K4: Summary Statistics
A5: ='Raw Data'!A5 -> Australian Open | B5: ='Raw Data'!B5 -> Jannik Sinner | C5: ='Raw Data'!C5 -> 1 | D5: ='Raw Data'!D5 -> 1 | E5: ='Raw Data'!J5 -> Final | F5: ='Raw Data'!K5 -> 7 | G5: ='Raw Data'!E5 -> Final | H5: ='Raw Data'!F5 -> 8 | I5: ='Raw Data'!L5 -> 1 | K5: Avg. Expected Score: | L5: =AVERAGE(ExpectedActual[Expected Score]) -> 1.9414062
A6: ='Raw Data'!A6 -> Australian Open | B6: ='Raw Data'!B6 -> Alexander Zverev | C6: ='Raw Data'!C6 -> 2 | D6: ='Raw Data'!D6 -> 2 | E6: ='Raw Data'!J6 -> Final | F6: ='Raw Data'!K6 -> 7 | G6: ='Raw Data'!E6 -> Final | H6: ='Raw Data'!F6 -> 7 | I6: ='Raw Data'!L6 -> 0 | K6: Avg. Actual Score: | L6: =AVERAGE(ExpectedActual[Actual Score]) -> 1.9921875
A7: ='Raw Data'!A7 -> Australian Open | B7: ='Raw Data'!B7 -> Nicolas Jarry | C7: ='Raw Data'!C7 -> 34 | D7: ='Raw Data'!D7 -> 0 | E7: ='Raw Data'!J7 -> R64 | F7: ='Raw Data'!K7 -> 2 | G7: ='Raw Data'!E7 -> R128 | H7: ='Raw Data'!F7 -> 1 | I7: ='Raw Data'!L7 -> -1 | K7: Avg. Performance Deviation: | L7: =AVERAGE(ExpectedActual[[Performance Deviation ]]) -> 0.046875
A8: ='Raw Data'!A8 -> Australian Open | B8: ='Raw Data'!B8 -> Tristan Schoolkate | C8: ='Raw Data'!C8 -> 173 | D8: ='Raw Data'!D8 -> 0 | E8: ='Raw Data'!J8 -> R128 | F8: ='Raw Data'!K8 -> 1 | G8: ='Raw Data'!E8 -> R64 | H8: ='Raw Data'!F8 -> 2 | I8: ='Raw Data'!L8 -> 1 | K8: Players Above Expectation: | L8: =COUNTIF(I5:I516,">0") -> 163
A9: ='Raw Data'!A9 -> Australian Open | B9: ='Raw Data'!B9 -> Taro Daniel | C9: ='Raw Data'!C9 -> 84 | D9: ='Raw Data'!D9 -> 0 | E9: ='Raw Data'!J9 -> R128 | F9: ='Raw Data'!K9 -> 1 | G9: ='Raw Data'!E9 -> R128 | H9: ='Raw Data'!F9 -> 1 | I9: ='Raw Data'!L9 -> 0 | K9: Players Matching Expectation: | L9: =COUNTIF(I5:I516,"=0") -> 215
A10: ='Raw Data'!A10 -> Australian Open | B10: ='Raw Data'!B10 -> Marcos Giron | C10: ='Raw Data'!C10 -> 45 | D10: ='Raw Data'!D10 -> 0 | E10: ='Raw Data'!J10 -> R64 | F10: ='Raw Data'!K10 -> 2 | G10: ='Raw Data'!E10 -> R32 | H10: ='Raw Data'!F10 -> 3 | I10: ='Raw Data'!L10 -> 1 | K10: Player Below Expectation: | L10: =COUNTIF(I5:I516,"<0") -> 134
A11: ='Raw Data'!A11 -> Australian Open | B11: ='Raw Data'!B11 -> Yannick Hanfmann | C11: ='Raw Data'!C11 -> 98 | D11: ='Raw Data'!D11 -> 0 | E11: ='Raw Data'!J11 -> R128 | F11: ='Raw Data'!K11 -> 1 | G11: ='Raw Data'!E11 -> R128 | H11: ='Raw Data'!F11 -> 1 | I11: ='Raw Data'!L11 -> 0
A12: ='Raw Data'!A12 -> Australian Open | B12: ='Raw Data'!B12 -> Tomas Martin Etcheverry | C12: ='Raw Data'!C12 -> 39 | D12: ='Raw Data'!D12 -> 0 | E12: ='Raw Data'!J12 -> R64 | F12: ='Raw Data'!K12 -> 2 | G12: ='Raw Data'!E12 -> R64 | H12: ='Raw Data'!F12 -> 2 | I12: ='Raw Data'!L12 -> 0
A13: ='Raw Data'!A13 -> Australian Open | B13: ='Raw Data'!B13 -> Flavio Cobolli | C13: ='Raw Data'!C13 -> 32 | D13: ='Raw Data'!D13 -> 32 | E13: ='Raw Data'!J13 -> R32 | F13: ='Raw Data'!K13 -> 3 | G13: ='Raw Data'!E13 -> R128 | H13: ='Raw Data'!F13 -> 1 | I13: ='Raw Data'!L13 -> -2
A14: ='Raw Data'!A14 -> Australian Open | B14: ='Raw Data'!B14 -> Stan Wawrinka | C14: ='Raw Data'!C14 -> 158 | D14: ='Raw Data'!D14 -> 0 | E14: ='Raw Data'!J14 -> R128 | F14: ='Raw Data'!K14 -> 1 | G14: ='Raw Data'!E14 -> R128 | H14: ='Raw Data'!F14 -> 1 | I14: ='Raw Data'!L14 -> 0
A15: ='Raw Data'!A15 -> Australian Open | B15: ='Raw Data'!B15 -> Hubert Hurkacz | C15: ='Raw Data'!C15 -> 18 | D15: ='Raw Data'!D15 -> 18 | E15: ='Raw Data'!J15 -> R32 | F15: ='Raw Data'!K15 -> 3 | G15: ='Raw Data'!E15 -> R64 | H15: ='Raw Data'!F15 -> 2 | I15: ='Raw Data'!L15 -> -1
A16: ='Raw Data'!A16 -> Australian Open | B16: ='Raw Data'!B16 -> Tallon Griekspoor | C16: ='Raw Data'!C16 -> 40 | D16: ='Raw Data'!D16 -> 0 | E16: ='Raw Data'!J16 -> R64 | F16: ='Raw Data'!K16 -> 2 | G16: ='Raw Data'!E16 -> R128 | H16: ='Raw Data'!F16 -> 1 | I16: ='Raw Data'!L16 -> -1
A17: ='Raw Data'!A17 -> Australian Open | B17: ='Raw Data'!B17 -> Dusan Lajovic | C17: ='Raw Data'!C17 -> 75 | D17: ='Raw Data'!D17 -> 0 | E17: ='Raw Data'!J17 -> R128 | F17: ='Raw Data'!K17 -> 1 | G17: ='Raw Data'!E17 -> R128 | H17: ='Raw Data'!F17 -> 1 | I17: ='Raw Data'!L17 -> 0
A18: ='Raw Data'!A18 -> Australian Open | B18: ='Raw Data'!B18 -> Miomir Kecmanovic | C18: ='Raw Data'!C18 -> 55 | D18: ='Raw Data'!D18 -> 0 | E18: ='Raw Data'!J18 -> R64 | F18: ='Raw Data'!K18 -> 2 | G18: ='Raw Data'!E18 -> R32 | H18: ='Raw Data'!F18 -> 3 | I18: ='Raw Data'!L18 -> 1
A19: ='Raw Data'!A19 -> Australian Open | B19: ='Raw Data'!B19 -> Matteo Berrettini | C19: ='Raw Data'!C19 -> 35 | D19: ='Raw Data'!D19 -> 0 | E19: ='Raw Data'!J19 -> R64 | F19: ='Raw Data'!K19 -> 2 | G19: ='Raw Data'!E19 -> R64 | H19: ='Raw Data'!F19 -> 2 | I19: ='Raw Data'!L19 -> 0
A20: ='Raw Data'!A20 -> Australian Open | B20: ='Raw Data'!B20 -> Gael Monfils | C20: ='Raw Data'!C20 -> 52 | D20: ='Raw Data'!D20 -> 0 | E20: ='Raw Data'!J20 -> R64 | F20: ='Raw Data'!K20 -> 2 | G20: ='Raw Data'!E20 -> R16 | H20: ='Raw Data'!F20 -> 4 | I20: ='Raw Data'!L20 -> 2
A21: ='Raw Data'!A21 -> Australian Open | B21: ='Raw Data'!B21 -> Cameron Norrie | C21: ='Raw Data'!C21 -> 48 | D21: ='Raw Data'!D21 -> 0 | E21: ='Raw Data'!J21 -> R64 | F21: ='Raw Data'!K21 -> 2 | G21: ='Raw Data'!E21 -> R128 | H21: ='Raw Data'!F21 -> 1 | I21: ='Raw Data'!L21 -> -1
A22: ='Raw Data'!A22 -> Australian Open | B22: ='Raw Data'!B22 -> Holger Rune | C22: ='Raw Data'!C22 -> 13 | D22: ='Raw Data'!D22 -> 13 | E22: ='Raw Data'!J22 -> R16 | F22: ='Raw Data'!K22 -> 4 | G22: ='Raw Data'!E22 -> R16 | H22: ='Raw Data'!F22 -> 4 | I22: ='Raw Data'!L22 -> 0
... A515: ='Raw Data'!A515 -> US Open | B515: ='Raw Data'!B515 -> Mattia Bellucci | C515: ='Raw Data'!C515 -> 63 | D515: ='Raw Data'!D515 -> 0 | E515: ='Raw Data'!J515 -> R64 | F515: ='Raw Data'!K515 -> 2 | G515: ='Raw Data'!E515 -> R64 | H515: ='Raw Data'!F515 -> 2 | I515: ='Raw Data'!L515 -> 0
A516: US Open | B516: ='Raw Data'!B516 -> Juncheng Shang | C516: ='Raw Data'!C516 -> 108 | D516: ='Raw Data'!D516 -> 0 | E516: ='Raw Data'!J516 -> R128 | F516: ='Raw Data'!K516 -> 1 | G516: ='Raw Data'!E516 -> R128 | H516: ='Raw Data'!F516 -> 1 | I516: ='Raw Data'!L516 -> 0

Sheet Tournament Comparison
A1: 2025 GRAND SLAM TOURNAMENT COMPARISON
A2: Comparing expected performance, actual performance and performance deviations across the four Grand Slam tournaments
A4: Tournament | B4: Avg. Expected Score | C4: Avg. Actual Score | D4: Avg. Performance Deviation | E4: Above Expectation | F4: Matching Expectation | G4: Below Expectation
A5: Australian Open | B5: =AVERAGEIF('Exp. vs Act.'!A:A,A5,'Exp. vs Act.'!F:F) -> 1.96875 | C5: =AVERAGEIF('Exp. vs Act.'!A:A,A5,'Exp. vs Act.'!H:H) -> 1.9921875 | D5: =AVERAGEIF('Exp. vs Act.'!A:A,A5,'Exp. vs Act.'!I:I) -> 0.0078125 | E5: {=SUMPRODUCT(('Exp. vs Act.'!$A$5:$A$516=A5)*('Exp. vs Act.'!$I$5:$I$516>0))} -> 40 | F5: =COUNTIFS('Exp. vs Act.'!$A$5:$A$516,A5,'Exp. vs Act.'!$I$5:$I$516,0) -> 52 | G5: {=SUMPRODUCT(('Exp. vs Act.'!$A$5:$A$516=A5)*('Exp. vs Act.'!$I$5:$I$516<0))} -> 36
A6: Roland Garros | B6: =AVERAGEIF('Exp. vs Act.'!A:A,A6,'Exp. vs Act.'!F:F) -> 1.9453125 | C6: =AVERAGEIF('Exp. vs Act.'!A:A,A6,'Exp. vs Act.'!H:H) -> 1.9921875 | D6: =AVERAGEIF('Exp. vs Act.'!A:A,A6,'Exp. vs Act.'!I:I) -> 0.046875 | E6: {=SUMPRODUCT(('Exp. vs Act.'!$A$5:$A$516=A6)*('Exp. vs Act.'!$I$5:$I$516>0))} -> 41 | F6: =COUNTIFS('Exp. vs Act.'!$A$5:$A$516,A6,'Exp. vs Act.'!$I$5:$I$516,0) -> 53 | G6: {=SUMPRODUCT(('Exp. vs Act.'!$A$5:$A$516=A6)*('Exp. vs Act.'!$I$5:$I$516<0))} -> 34
A7: Wimbledon | B7: =AVERAGEIF('Exp. vs Act.'!A:A,A7,'Exp. vs Act.'!F:F) -> 1.90625 | C7: =AVERAGEIF('Exp. vs Act.'!A:A,A7,'Exp. vs Act.'!H:H) -> 1.9921875 | D7: =AVERAGEIF('Exp. vs Act.'!A:A,A7,'Exp. vs Act.'!I:I) -> 0.0859375 | E7: {=SUMPRODUCT(('Exp. vs Act.'!$A$5:$A$516=A7)*('Exp. vs Act.'!$I$5:$I$516>0))} -> 47 | F7: =COUNTIFS('Exp. vs Act.'!$A$5:$A$516,A7,'Exp. vs Act.'!$I$5:$I$516,0) -> 49 | G7: {=SUMPRODUCT(('Exp. vs Act.'!$A$5:$A$516=A7)*('Exp. vs Act.'!$I$5:$I$516<0))} -> 32
A8: US Open | B8: =AVERAGEIF('Exp. vs Act.'!A:A,A8,'Exp. vs Act.'!F:F) -> 1.9453125 | C8: =AVERAGEIF('Exp. vs Act.'!A:A,A8,'Exp. vs Act.'!H:H) -> 1.9921875 | D8: =AVERAGEIF('Exp. vs Act.'!A:A,A8,'Exp. vs Act.'!I:I) -> 0.046875 | E8: {=SUMPRODUCT(('Exp. vs Act.'!$A$5:$A$516=A8)*('Exp. vs Act.'!$I$5:$I$516>0))} -> 35 | F8: =COUNTIFS('Exp. vs Act.'!$A$5:$A$516,A8,'Exp. vs Act.'!$I$5:$I$516,0) -> 61 | G8: {=SUMPRODUCT(('Exp. vs Act.'!$A$5:$A$516=A8)*('Exp. vs Act.'!$I$5:$I$516<0))} -> 32

Sheet Statistical Analysis 
A1: Statistical Analysis of Ranking and Tournament Performance
A2: Examining the relationship between pre-tournament ATP rankings, expected performance and actual Grand Slam results
A4: Descriptive Statistics | F4: Descriptive Statistics Interpretation
A6: Statistic | B6: Value
A7: Average Expected Score | B7: =AVERAGE('Exp. vs Act.'!F5:F516) -> 1.9414062 | F7: Average Expected Score | G7: Across the sample, the average ranking-based expected performance was 1.9414, indicating that the typical player was expected to exit relatively early in the tournament because the sample contains many players outside the top ranking bands.
A8: Average Actual Score | B8: =AVERAGE('Exp. vs Act.'!H5:H516) -> 1.9921875 | F8: Average Actual Score | G8: The average actual performance score was 1.9922, which was slightly higher than the average expected score. This suggests that, overall, players progressed marginally further than their ranking-based expectations.
A9: Average Performance Deviation | B9: =AVERAGE('Exp. vs Act.'!I5:I516) -> 0.046875 | F9: Average Performance Deviation | G9: The average deviation was 0.0469, which is very close to zero. This indicates that, across the full sample, actual performance was broadly similar to the ranking-based expectations, with only a small positive average difference.
A10: Median Performance Deviation | B10: =MEDIAN('Exp. vs Act.'!I5:I516) -> 0 | F10: Median Performance Deviation | G10: The median deviation was 0, meaning the middle observation matched its expected performance. This also shows that the small positive average was not driven by every player outperforming expectations; performance varied substantially around the expected outcome.
A11: Standard Deviation of Performance Deviation | B11: =_xlfn.STDEV.S('Exp. vs Act.'!I5:I516) -> 1.2519066 | F11: Standard Deviation of Performance Deviation | G11: The standard deviation was 1.2519, showing considerable variation in performance deviations. Players' actual tournament outcomes could therefore differ noticeably from the round expected from their pre-tournament ranking.
A12: Minimum Performance Deviation | B12: =MIN('Exp. vs Act.'!I5:I516) -> -5 | F12: Minimum Performance Deviation | G12: The minimum deviation was −5, meaning at least one player exited as many as five performance-score levels below their ranking-based expectation.
A13: Maximum Performance Deviation | B13: =MAX('Exp. vs Act.'!I5:I516) -> 3 | F13: Maximum Performance Deviation | G13: The maximum deviation was +3, meaning the largest positive deviation was three performance-score levels above the player's ranking-based expectation.

Sheet Statistical Analysis 2
A1: Statistical Analysis of Ranking and Tournament Performance
A2: Examining the relationship between pre-tournament ATP rankings, expected performance and actual Grand Slam results
A4: Correlation Analysis | F4: Correlation Interpretation
A6: Variable 1 | B6: Variable 2 | C6: Correlation Coefficient
A7: ATP Ranking Before Tournament | B7: Actual Score | C7: {=CORREL(_xlfn._xlws.FILTER('Exp. vs Act.'!C5:C516,'Exp. vs Act.'!C5:C516<>""),_xlfn._xlws.FILTER('Exp. vs Act.'!H5:H516,'Exp. vs Act.'!C5:C516<>""))} -> -0.25575762 | F7: ATP Ranking vs Actual Score | G7: The correlation of -0.2558 indicates a modest negative relationship between pre-tournament ATP ranking and actual tournament performance. Because a lower ATP ranking represents a higher-ranked player, the negative relationship is consistent with higher-ranked players tending to achieve higher performance scores. However, the relatively small magnitude indicates substantial variation in tournament outcomes.
A8: Expected Score | B8: Actual Score | C8: =CORREL('Exp. vs Act.'!F5:F516,'Exp. vs Act.'!H5:H516) -> 0.57502664 | F8: Expected Score vs Actual Score | G8: The correlation of 0.5750 indicates a moderate positive relationship between ranking-based Expected Score and Actual Score. Players with higher expected performance scores generally achieved higher actual performance scores, although the relationship is not perfect and considerable variation remained between expectations and results.

Sheet Statistical Analysis 3
A1: Statistical Analysis of Ranking and Tournament Performance
A2: Examining the relationship between pre-tournament ATP rankings, expected performance and actual Grand Slam results
A4: Regression Analysis | F4: Regression Interpretations
A6: Model | B6: Value
A7: Regression Equation | B7: ="Actual Score = "&TEXT(B9,"0.0000")&" + "&TEXT(B8,"0.0000")&" × Expected Score" -> Actual Score = 0.8521 + 0.5873 × Expected Score
A8: Slope (Coefficient) | B8: {=SLOPE(_xlfn._xlws.FILTER('Exp. vs Act.'!H5:H516,'Exp. vs Act.'!F5:F516<>""),_xlfn._xlws.FILTER('Exp. vs Act.'!F5:F516,'Exp. vs Act.'!F5:F516<>""))} -> 0.58725476
A9: Intercept | B9: {=INTERCEPT(_xlfn._xlws.FILTER('Exp. vs Act.'!H5:H516,'Exp. vs Act.'!F5:F516<>""),_xlfn._xlws.FILTER('Exp. vs Act.'!F5:F516,'Exp. vs Act.'!F5:F516<>""))} -> 0.85208744
A10: R-squared | B10: {=RSQ(_xlfn._xlws.FILTER('Exp. vs Act.'!H5:H516,'Exp. vs Act.'!F5:F516<>""),_xlfn._xlws.FILTER('Exp. vs Act.'!F5:F516,'Exp. vs Act.'!F5:F516<>""))} -> 0.33065563
A11: Standard Error of Regression | B11: =STEYX('Exp. vs Act.'!H5:H516,'Exp. vs Act.'!F5:F516) -> 1.1247894
A12: Observations | B12: =COUNT('Exp. vs Act.'!F5:F516) -> 512
A13: Standard Error of Coefficient | B13: =INDEX(LINEST('Exp. vs Act.'!H5:H516,'Exp. vs Act.'!F5:F516,TRUE,TRUE),2,1) -> 0.036998005
A14: t-statistic | B14: =B8/B13 -> 15.872606
A15: p-value | B15: =_xlfn.T.DIST.2T(ABS(B14),B12-2) -> 2.1242463e-46

Sheet Python Analysis
A1: PYTHON ANALYSIS - ATP GRAND SLAM PERFORMANCE
A2: 2025 Australian Open, Roland Garros, Wimbledon & US Open — 512 player-tournament observations
A4: Purpose of Analysis
A5: Python was used to conduct additional analysis of the relationship between pre-tournament ATP ranking and tournament performance, focusing on actual performance, performance relative to expectations and consistency across the four 2025 Grand Slam tournaments.
A8: 1. Ranking Group Performance | F8: 2. Ranking vs Expectations | J8: 3. Variation in Performance Deviation | N8: 4. Ranking vs Actual Score Correlation
A9: Question: How does tournament performance differ across pre-tournament ATP ranking groups? | F9: Question: Do higher-ranked players perform above or below their expected tournament outcome? | J9: Question: How consistent is performance relative to expectations within each ranking group? | N9: Question: What is the relationship between pre-tournament ATP ranking and tournament performance?
B10: Ranking Group | C10: Observations | D10: Average Actual Score | G10: Ranking Group | H10: Average Performance Deviation | K10: Ranking Group | L10: Standard Deviation of Performance Deviation | O10: Measure | P10: Result
B11: 1-10 | C11: 40 | D11: 4.225 | G11: 1-10 | H11: -1.175 | K11: 1-10 | L11: 1.972731 | O11: Pearson Correlation | P11: -0.2558
B12: 11-20 | C12: 37 | D12: 2.7568 | G12: 11-20 | H12: -0.8378 | K12: 11-20 | L12: 1.280484 | O12: Observations | P12: 512
B13: 21-50 | C13: 115 | D13: 1.9826 | G13: 21-50 | H13: -0.4087 | K13: 21-50 | L13: 1.183925
B14: 51-100 | C14: 174 | D14: 1.6897 | G14: 51-100 | H14: 0.3908 | K14: 51-100 | L14: 0.983756
B15: 101+ | C15: 144 | D15: 1.5625 | G15: 101+ | H15: 0.5625 | K15: 101+ | L15: 0.799639
A17: Interpretation | C17: Python Methods | F17: Interpretation | H17: Python Methods | J17: Interpretation | L17: Python Methods | N17: Interpretation | P17: Python Method
A18: Average Actual Score declined as pre-tournament ranking position moved further from the top of the rankings. Players ranked 1–10 averaged 4.23 performance points compared with 1.56 for players ranked 101+. This indicates a clear association between higher pre-tournament ranking and stronger tournament performance within the dataset. | C18: Methods used: pd.cut(), groupby(), count() and mean() | F18: Although higher-ranked players achieved higher absolute Actual Scores, their average Performance Deviation was negative. Lower-ranked players recorded positive average deviations. This highlights the distinction between absolute tournament performance and performance relative to pre-tournament expectations. | H18: Methods used: groupby(), mean() | J18: Variation in Performance Deviation was highest among players ranked 1–10, with a standard deviation of 1.97, and lowest among players ranked 101+, at 0.80. This indicates that performance relative to expectations was more variable among higher-ranked players within the dataset. | L18: Methods used: groupby(), std() | N18: The correlation coefficient of -0.2558 indicates a negative association between numerical ATP ranking and Actual Score. Because a lower ranking number represents a higher-ranked player, the result is consistent with higher-ranked players tending to achieve higher tournament performance. However, the correlation is relatively modest, indicating that ranking alone does not fully explain differences in tournament performance. | P18: Method used: corr()

Sheet Python Analysis 2
A1: PYTHON ANALYSIS - ATP GRAND SLAM PERFORMANCE
A2: Statistical & Player-Level Analysis — 2025 ATP Grand Slam Men’s Singles
A5: 5. Consistent Player Performance Relative to Expectations
A6: Question: Which players recorded the strongest average Performance Deviation across multiple Grand Slam tournaments?
B7: Player | C7: Grand Slams | D7: Average Performance Deviation | E7: Total Performance Deviation
B8: Adrian Mannarino | C8: 3 | D8: 1.67 | E8: +5
B9: Cameron Norrie | C9: 4 | D9: 1.5 | E9: +6
B10: Kamil Majchrzak | C10: 4 | D10: 1.25 | E10: +5
B11: Daniel Altmaier | C11: 4 | D11: 1 | E11: +4
B12: Ethan Quinn | C12: 3 | D12: 1 | E12: +3
B13: Pablo Carreno Busta | C13: 3 | D13: 1 | E13: +3
B14: Sebastian Ofner | C14: 3 | D14: 1 | E14: +3
B15: Marton Fucsovics | C15: 3 | D15: 1 | E15: +3
B16: Joao Fonseca | C16: 4 | D16: 1 | E16: +4
B17: Jan Lennard Struff | C17: 4 | D17: 1 | E17: +4
A19: Interpretation | C19: Python Methods
A20: Among players with at least three Grand Slam observations, Adrian Mannarino recorded the highest average Performance Deviation at +1.67, followed by Cameron Norrie at +1.50. The analysis identifies players who recorded positive performance deviations across multiple Grand Slam appearances. | C20: Methods used: groupby(), agg(), sort_values() and head()
